```python

from django.db import transaction

from apps.ad.models import SloganWord

with transaction.atomic():
    SloganWord.objects.create(hash_val='12', word='12', flag=3)
    with transaction.atomic():
        SloganWord.objects.create(hash_val='12', word='12', flag=3)
        raise Exception()
```


```

set autocommit=0
set autocommit=0
INSERT INTO `slogan_word` (`hash_val`, `word`, `flag`) VALUES ('12', '12', 3)
commit
set autocommit=1
SAVEPOINT `s140448177551104_x2`
set autocommit=0
INSERT INTO `slogan_word` (`hash_val`, `word`, `flag`) VALUES ('12', '12', 3)
rollback
set autocommit=1
ROLLBACK TO SAVEPOINT `s140448177551104_x2`
RELEASE SAVEPOINT `s140448177551104_x2`
rollback
set autocommit=1

```

问题： create操作好像启动了commit操作？导致无法正常回滚两个事务？

原因： 忘记使用using了。。。。默认是default。但是model不是default

改成`with transaction.atomic(using=SloganWord.connection_name):`后：

```
set autocommit=0
INSERT INTO `slogan_word` (`hash_val`, `word`, `flag`) VALUES ('12', '12', 3)
SAVEPOINT `s140445035808512_x1`
INSERT INTO `slogan_word` (`hash_val`, `word`, `flag`) VALUES ('12', '12', 3)
ROLLBACK TO SAVEPOINT `s140445035808512_x1`
RELEASE SAVEPOINT `s140445035808512_x1`
rollback
set autocommit=1
```

savepoint默认是True，改为False后，停止内层代码库中的保存点的创建
```python
from django.db import transaction

from apps.ad.models import SloganWord

with transaction.atomic(using=SloganWord.connection_name, savepoint=False):
    SloganWord.objects.create(hash_val='12', word='12', flag=3)
    with transaction.atomic(using=SloganWord.connection_name, savepoint=False):
        SloganWord.objects.create(hash_val='12', word='12', flag=3)
        raise Exception()

```

```
set autocommit=0
INSERT INTO `slogan_word` (`hash_val`, `word`, `flag`) VALUES ('12', '12', 3)
INSERT INTO `slogan_word` (`hash_val`, `word`, `flag`) VALUES ('12', '12', 3)
rollback
set autocommit=1

```
